2025-06-13 13:11:18,127 INFO: Ultraguard startup [in C:\Users\adams\Documents\Ultraguard\app\__init__.py:73]
2025-06-13 17:17:08,274 INFO: Ultraguard startup [in C:\Users\adams\Documents\Ultraguard\app\__init__.py:73]
2025-06-14 20:59:11,230 INFO: Ultraguard startup [in C:\Users\adams\Documents\Ultraguard\app\__init__.py:73]
2025-06-14 21:02:21,634 INFO: Ultraguard startup [in C:\Users\adams\Documents\Ultraguard\app\__init__.py:82]
2025-06-14 21:02:55,735 INFO: Ultraguard startup [in C:\Users\adams\Documents\Ultraguard\app\__init__.py:82]
2025-06-14 21:03:37,120 INFO: Ultraguard startup [in C:\Users\adams\Documents\Ultraguard\app\__init__.py:82]
2025-06-14 21:09:46,064 INFO: Ultraguard startup [in C:\Users\adams\Documents\Ultraguard\app\__init__.py:82]
2025-06-14 21:13:38,960 INFO: Ultraguard startup [in C:\Users\adams\Documents\Ultraguard\app\__init__.py:79]
2025-06-14 21:23:58,728 INFO: Ultraguard startup [in C:\Users\adams\Documents\Ultraguard\app\__init__.py:79]
2025-06-14 21:25:46,013 INFO: Ultraguard startup [in C:\Users\adams\Documents\Ultraguard\app\__init__.py:79]
2025-06-14 21:27:25,175 INFO: Ultraguard startup [in C:\Users\adams\Documents\Ultraguard\app\__init__.py:79]
2025-06-14 21:31:57,278 INFO: Ultraguard startup [in C:\Users\adams\Documents\Ultraguard\app\__init__.py:79]
2025-06-14 21:37:40,368 ERROR: Exception on /portal/login [POST] [in C:\Users\adams\Documents\Ultraguard\venv\Lib\site-packages\flask\app.py:875]
Traceback (most recent call last):
  File "C:\Users\adams\Documents\Ultraguard\venv\Lib\site-packages\sqlalchemy\engine\base.py", line 1963, in _exec_single_context
    self.dialect.do_execute(
    ~~~~~~~~~~~~~~~~~~~~~~~^
        cursor, str_statement, effective_parameters, context
        ^^^^^^^^^^^^^^^^^^^^^^^^^^^^^^^^^^^^^^^^^^^^^^^^^^^^
    )
    ^
  File "C:\Users\adams\Documents\Ultraguard\venv\Lib\site-packages\sqlalchemy\engine\default.py", line 943, in do_execute
    cursor.execute(statement, parameters)
    ~~~~~~~~~~~~~~^^^^^^^^^^^^^^^^^^^^^^^
sqlite3.OperationalError: no such table: system_user

The above exception was the direct cause of the following exception:

Traceback (most recent call last):
  File "C:\Users\adams\Documents\Ultraguard\venv\Lib\site-packages\flask\app.py", line 1511, in wsgi_app
    response = self.full_dispatch_request()
  File "C:\Users\adams\Documents\Ultraguard\venv\Lib\site-packages\flask\app.py", line 919, in full_dispatch_request
    rv = self.handle_user_exception(e)
  File "C:\Users\adams\Documents\Ultraguard\venv\Lib\site-packages\flask\app.py", line 917, in full_dispatch_request
    rv = self.dispatch_request()
  File "C:\Users\adams\Documents\Ultraguard\venv\Lib\site-packages\flask\app.py", line 902, in dispatch_request
    return self.ensure_sync(self.view_functions[rule.endpoint])(**view_args)  # type: ignore[no-any-return]
           ~~~~~~~~~~~~~~~~~~~~~~~~~~~~~~~~~~~~~~~~~~~~~~~~~~~~^^^^^^^^^^^^^
  File "C:\Users\adams\Documents\Ultraguard\app\client_portal\routes.py", line 38, in login
    ).first()
      ~~~~~^^
  File "C:\Users\adams\Documents\Ultraguard\venv\Lib\site-packages\sqlalchemy\orm\query.py", line 2759, in first
    return self.limit(1)._iter().first()  # type: ignore
           ~~~~~~~~~~~~~~~~~~~^^
  File "C:\Users\adams\Documents\Ultraguard\venv\Lib\site-packages\sqlalchemy\orm\query.py", line 2857, in _iter
    result: Union[ScalarResult[_T], Result[_T]] = self.session.execute(
                                                  ~~~~~~~~~~~~~~~~~~~~^
        statement,
        ^^^^^^^^^^
        params,
        ^^^^^^^
        execution_options={"_sa_orm_load_options": self.load_options},
        ^^^^^^^^^^^^^^^^^^^^^^^^^^^^^^^^^^^^^^^^^^^^^^^^^^^^^^^^^^^^^^
    )
    ^
  File "C:\Users\adams\Documents\Ultraguard\venv\Lib\site-packages\sqlalchemy\orm\session.py", line 2365, in execute
    return self._execute_internal(
           ~~~~~~~~~~~~~~~~~~~~~~^
        statement,
        ^^^^^^^^^^
    ...<4 lines>...
        _add_event=_add_event,
        ^^^^^^^^^^^^^^^^^^^^^^
    )
    ^
  File "C:\Users\adams\Documents\Ultraguard\venv\Lib\site-packages\sqlalchemy\orm\session.py", line 2251, in _execute_internal
    result: Result[Any] = compile_state_cls.orm_execute_statement(
                          ~~~~~~~~~~~~~~~~~~~~~~~~~~~~~~~~~~~~~~~^
        self,
        ^^^^^
    ...<4 lines>...
        conn,
        ^^^^^
    )
    ^
  File "C:\Users\adams\Documents\Ultraguard\venv\Lib\site-packages\sqlalchemy\orm\context.py", line 306, in orm_execute_statement
    result = conn.execute(
        statement, params or {}, execution_options=execution_options
    )
  File "C:\Users\adams\Documents\Ultraguard\venv\Lib\site-packages\sqlalchemy\engine\base.py", line 1415, in execute
    return meth(
        self,
        distilled_parameters,
        execution_options or NO_OPTIONS,
    )
  File "C:\Users\adams\Documents\Ultraguard\venv\Lib\site-packages\sqlalchemy\sql\elements.py", line 523, in _execute_on_connection
    return connection._execute_clauseelement(
           ~~~~~~~~~~~~~~~~~~~~~~~~~~~~~~~~~^
        self, distilled_params, execution_options
        ^^^^^^^^^^^^^^^^^^^^^^^^^^^^^^^^^^^^^^^^^
    )
    ^
  File "C:\Users\adams\Documents\Ultraguard\venv\Lib\site-packages\sqlalchemy\engine\base.py", line 1637, in _execute_clauseelement
    ret = self._execute_context(
        dialect,
    ...<8 lines>...
        cache_hit=cache_hit,
    )
  File "C:\Users\adams\Documents\Ultraguard\venv\Lib\site-packages\sqlalchemy\engine\base.py", line 1842, in _execute_context
    return self._exec_single_context(
           ~~~~~~~~~~~~~~~~~~~~~~~~~^
        dialect, context, statement, parameters
        ^^^^^^^^^^^^^^^^^^^^^^^^^^^^^^^^^^^^^^^
    )
    ^
  File "C:\Users\adams\Documents\Ultraguard\venv\Lib\site-packages\sqlalchemy\engine\base.py", line 1982, in _exec_single_context
    self._handle_dbapi_exception(
    ~~~~~~~~~~~~~~~~~~~~~~~~~~~~^
        e, str_statement, effective_parameters, cursor, context
        ^^^^^^^^^^^^^^^^^^^^^^^^^^^^^^^^^^^^^^^^^^^^^^^^^^^^^^^
    )
    ^
  File "C:\Users\adams\Documents\Ultraguard\venv\Lib\site-packages\sqlalchemy\engine\base.py", line 2351, in _handle_dbapi_exception
    raise sqlalchemy_exception.with_traceback(exc_info[2]) from e
  File "C:\Users\adams\Documents\Ultraguard\venv\Lib\site-packages\sqlalchemy\engine\base.py", line 1963, in _exec_single_context
    self.dialect.do_execute(
    ~~~~~~~~~~~~~~~~~~~~~~~^
        cursor, str_statement, effective_parameters, context
        ^^^^^^^^^^^^^^^^^^^^^^^^^^^^^^^^^^^^^^^^^^^^^^^^^^^^
    )
    ^
  File "C:\Users\adams\Documents\Ultraguard\venv\Lib\site-packages\sqlalchemy\engine\default.py", line 943, in do_execute
    cursor.execute(statement, parameters)
    ~~~~~~~~~~~~~~^^^^^^^^^^^^^^^^^^^^^^^
sqlalchemy.exc.OperationalError: (sqlite3.OperationalError) no such table: system_user
[SQL: SELECT system_user.id AS system_user_id, system_user.username AS system_user_username, system_user.password_hash AS system_user_password_hash, system_user.email AS system_user_email, system_user.role AS system_user_role, system_user.is_active AS system_user_is_active, system_user.client_id AS system_user_client_id, system_user.created_at AS system_user_created_at, system_user.last_login_at AS system_user_last_login_at 
FROM system_user 
WHERE system_user.username = ? OR system_user.email = ?
 LIMIT ? OFFSET ?]
[parameters: ('clientadmin', 'clientadmin', 1, 0)]
(Background on this error at: https://sqlalche.me/e/20/e3q8)
2025-06-14 21:37:40,588 ERROR: Server Error: 500 Internal Server Error: The server encountered an internal error and was unable to complete your request. Either the server is overloaded or there is an error in the application. [in C:\Users\adams\Documents\Ultraguard\app\__init__.py:110]
2025-06-14 21:43:37,310 INFO: Ultraguard startup [in C:\Users\adams\Documents\Ultraguard\app\__init__.py:79]
2025-06-14 21:44:22,017 INFO: Ultraguard startup [in C:\Users\adams\Documents\Ultraguard\app\__init__.py:79]
2025-06-14 21:44:36,912 INFO: Ultraguard startup [in C:\Users\adams\Documents\Ultraguard\app\__init__.py:79]
2025-06-14 21:44:52,438 INFO: Ultraguard startup [in C:\Users\adams\Documents\Ultraguard\app\__init__.py:79]
2025-06-14 21:45:57,122 INFO: Ultraguard startup [in C:\Users\adams\Documents\Ultraguard\app\__init__.py:79]
2025-06-14 21:46:26,936 INFO: Ultraguard startup [in C:\Users\adams\Documents\Ultraguard\app\__init__.py:79]
2025-06-14 21:47:28,203 INFO: Ultraguard startup [in C:\Users\adams\Documents\Ultraguard\app\__init__.py:79]
2025-06-14 21:47:41,262 INFO: Ultraguard startup [in C:\Users\adams\Documents\Ultraguard\app\__init__.py:79]
2025-06-18 15:53:55,631 INFO: Ultraguard startup [in C:\Users\adams\Documents\Ultraguard\app\__init__.py:79]
